Workbook

Sheet Instrucciones
A1: Nada sin fuente · Plantilla de conteo del experimento (semana 1) · Equipo de 3
A2: Sirve para clasificar referencias por consulta y tratamiento, calcular proporciones con intervalo y reportar el desacuerdo de clasificación.
A4: Quién es quién
A5: Q1, Q2, Q3 | B5: Son las TRES CONSULTAS, una por integrante (no los tratamientos). Q1 = Integrante 1 (tú), Q2 = Integrante 2, Q3 = Integrante 3. Cambia los nombres en la celda de color junto a cada bloque si quieres usar nombres reales.
A6: A, B, C | B6: Son los TRES TRATAMIENTOS. Cada consulta se corre en los tres: A = chat sin fuentes ni navegación (control); B = buscador conectado a bases bibliográficas (Consensus); C = contexto cerrado con sus propios PDF. Son 3 consultas × 3 tratamientos = 9 corridas en total.
A7: Cómo usarla
A8: 1. Registro | B8: Completa la hoja «Registro»: hay una fila por cada combinación consulta × tratamiento (9 filas). Cada integrante llena las 3 filas de su propia consulta (una por tratamiento) con herramienta, fecha y el prompt exacto.
A9: 2. Regla de selección | B9: Ya está fijada abajo en 5 referencias por respuesta (ajústala si tu equipo decidió otro número; si cambias el número tendría que rehacerse la hoja «Referencias»).
A10: 3. Clasificar | B10: En «Referencias», abre cada documento (DOI o URL) y clasifícalo en las columnas amarillas. LOS TRES INTEGRANTES clasifican las MISMAS 45 referencias (no solo las de su propia consulta), cada uno en su columna, sin consultarse ni mirar las de los demás. Trabaja en tu propia copia del archivo y luego se juntan las columnas.
A11: 4. Consenso | B11: Donde la columna «¿Coincide?» diga «No», discutan y anoten la clasificación final acordada. Esa es la que usa la hoja «Conteo».
A12: 5. Conteo | B12: La hoja «Conteo» calcula solo: n, categorías, proporción utilizable con intervalo (Wilson y Clopper-Pearson) por tratamiento, y el desacuerdo de clasificación. No escribas nada allí salvo el nivel de confianza.
A13: Un solo archivo para el equipo | B13: Este archivo es COMPARTIDO. Lo único que se hace en copias separadas es la clasificación a ciegas (paso 3); todo lo demás —referencias, registro, clasificación final, conteos— vive en un único archivo maestro.
A14: Colores
A15: Amarillo + letra azul | B15: Celdas que deben llenar ustedes.
A16: Gris | B16: Precargado desde la salida de Consensus para Q1 (CSV y tabla «Estudios Prioritarios»). Verifíquenlo: no es bibliografía aceptada.
A17: Rosado / verde / azul claro (en «Referencias») | B17: Marcan a qué consulta pertenece cada bloque de filas: Q1, Q2, Q3.
A18: Sin relleno | B18: Fórmulas. No las modifiquen.
A19: Categorías (según el enunciado)
A20: Utilizable | B20: Existe (se encuentra por DOI o título) y dice lo que se le atribuye.
A21: Existe pero no dice eso | B21: La referencia es real, pero la afirmación no se sostiene en el texto.
A22: No existe | B22: No se encuentra por DOI ni por título.
A23: Advertencia sobre las columnas H e I de Q1-B | B23: «¿Trata cobro por crédito?» y «Alerta preliminar» en las filas de Q1-B salen de una comparación hecha con ayuda de Claude entre la tabla de prioritarios y los abstracts del CSV. NO es una verificación: no se abrieron los documentos. Decláralo en el «Uso de IA» y no lo uses como fuente; lo que cuenta es lo que ustedes verifiquen (columna «Ubicación»).
A24: «Verificado por» | B24: Debe ser el nombre de quien realmente abrió el documento. Es lo que exige la tabla de trazabilidad.
A26: Regla de selección de referencias | B26: 5 referencias por respuesta, las primeras 5 que entregó la herramienta.

Sheet Referencias
A1: Referencias por consulta y tratamiento (una fila por referencia)
A2: Bloques de 5 filas: primero por TRATAMIENTO (A, B, C) y dentro de cada uno, por CONSULTA (Q1, Q2, Q3 — el color de fondo de la columna «Consulta» las distingue). El bloque Q1 dentro de B trae precargada, en gris, la salida de Consensus.
A3: LOS TRES INTEGRANTES clasifican las 45 filas completas (no solo las de su propia consulta).
A5: ID | B5: Trat. | C5: Consulta | D5: Referencia (autores, año, título) | E5: Revista / fuente | F5: DOI o URL | G5: Afirmación que la herramienta le atribuye | H5: ¿Trata cobro por crédito? (preliminar) | I5: Alerta preliminar (tabla vs. abstract del CSV) | J5: ¿DOI/URL resuelve? | K5: Clasificación · Integrante 1 | L5: Clasificación · Integrante 2 | M5: Clasificación · Integrante 3 | N5: ¿Coincide? | O5: Clasificación final | P5: Ubicación (página o cita textual) | Q5: Verificado por | R5: Fecha | S5: Notas
A6: A-Q1-01 | B6: A | C6: Q1 | D6: Volk, A., Plinske, M., & Bell, R. (2017). The impact of plateau tuition structures on student credit loads and institutional revenues. | E6: Journal of Higher Education Policy and Management, 39(4), 412–428 | F6: 10.1080/1360080X.2017.1330801 | G6: Carga promedio de 13.1 créditos/sem. bajo per-credit vs. 13.9 bajo plateau. | H6: Sí: plateau vs. per-credit y créditos/semestre | I6: DOI verificado: no resuelve a este artículo (resuelve a un artículo no relacionado). No se encontró rastro de Volk, Plinske & Bell en esa revista. Fuerte indicio de referencia inventada. | J6: No | K6: No existe | L6: No existe | M6: No existe | N6: =IF(COUNTA(K6:M6)<2,"",IF(SUMPRODUCT((K6:M6<>"")/COUNTIF(K6:M6,K6:M6&""))=1,"Sí","No")) -> Sí | O6: No existe
A7: A-Q1-02 | B7: A | C7: Q1 | D7: Monks, J., & Tenliberg, R. (2008). Tuition price structures and student enrollment decisions in private higher education. | E7: Economics of Education Review, 27(6), 687–698 | F7: 10.1016/j.econedurev.2007.09.004 | G7: Per-credit incrementa la probabilidad de tiempo parcial o reducir 1–2 asignaturas por semestre. | H7: Sí: per-credit y decisión de tiempo parcial | I7: Sin verificar aún. "Financial Higher Education Quarterly" (ver A-Q1-03) y "Journal of Student Financial Aid" con ese DOI (ver A-Q1-04) no dan confianza; revisar con el mismo cuidado. | J7: Sí | K7: Utilizable | L7: Utilizable | M7: Utilizable | N7: =IF(COUNTA(K7:M7)<2,"",IF(SUMPRODUCT((K7:M7<>"")/COUNTIF(K7:M7,K7:M7&""))=1,"Sí","No")) -> Sí | O7: Utilizable | P7: “Tuition price structures significantly affect enrollment decisions” (abstract) | Q7: Integrante 1 | R7: 46292 | S7: DOI 10.1016/j.econedurev.2007.09.004, verificado contra abstract.
A8: A-Q1-03 | B8: A | C8: Q1 | D8: Tidball, O., Smith, J., & Miller, K. (2015). Marginal costs and course taking: Evidence from public university pricing schemes. | E8: Financial Higher Education Quarterly, 41(2), 145–162 | F8: 10.1007/s10734-014-9811-1 | G8: Elasticidad de demanda de créditos de −0.18 bajo strict per-credit. | H8: Sí: costo marginal por crédito y elasticidad | I8: El DOI (10.1007/s10734-...) es un prefijo real de Springer/Higher Education, pero "Financial Higher Education Quarterly" no aparece como revista conocida del área. Verificar si el DOI resuelve. | J8: Sí | K8: Existe pero no dice eso | L8: Existe pero no dice eso | M8: Utilizable | N8: =IF(COUNTA(K8:M8)<2,"",IF(SUMPRODUCT((K8:M8<>"")/COUNTIF(K8:M8,K8:M8&""))=1,"Sí","No")) -> No | O8: Existe pero no dice eso
A9: A-Q1-04 | B9: A | C9: Q1 | D9: Gansemer-Topf, A., Matney, M., & Pallas, M. (2018). Evaluating the financial and academic trade-offs of tuition structure changes. | E9: Journal of Student Financial Aid, 48(1), 33–51 | F9: 10.55770/jsfa.v48i1.1042 | G9: Per-credit genera más ingreso por crédito en cargas bajas (1–11) pero reduce recaudo agregado por deserción antes del 5º semestre. | H9: Sí: per-credit y recaudo por carga baja | I9: El DOI (10.55770/...) usa un prefijo poco común; "Journal of Student Financial Aid" es una revista real pero hay que confirmar que el número y el artículo existan. Verificar. | J9: No | K9: No existe | L9: No existe | M9: No existe | N9: =IF(COUNTA(K9:M9)<2,"",IF(SUMPRODUCT((K9:M9<>"")/COUNTIF(K9:M9,K9:M9&""))=1,"Sí","No")) -> Sí | O9: No existe
A10: A-Q1-05 | B10: A | C10: Q1 | D10: Denning, J. T., Marx, B. M., & Turner, L. J. (2019). Proportional pricing and student success: Evidence from higher education pricing reforms. | E10: American Economic Journal: Economic Policy, 11(2), 110–138 | F10: 10.1257/pol.20170412 | G10: Eliminar el costo marginal (proportional pricing) estimula finalización de asignaturas sin bajar el GPA. | H10: Sí: eliminación de costo marginal (proportional pricing) | I10: Denning, Marx & Turner (2019) en AEJ: Economic Policy es un patrón de cita plausible (autores que sí trabajan el tema); vale la pena verificar primero, podría ser el único "utilizable" de los cinco. | J10: Sí | K10: Utilizable | L10: Utilizable | M10: Utilizable | N10: =IF(COUNTA(K10:M10)<2,"",IF(SUMPRODUCT((K10:M10<>"")/COUNTIF(K10:M10,K10:M10&""))=1,"Sí","No")) -> Sí | O10: No existe | Q10: Integrante 1 | R10: 46292
A11: A-Q2-01 | B11: A | C11: Q2 | D11: Knight, W. E., & Hakel, M. D. (2013). Curricular Load and Academic Progress: The Revenue Implications of Flat-Rate vs. Per-Credit Tuition. | E11: AIR Professional File (Association for Institutional Research) | F11: https://www.airweb.org/resources/publications/professional-file?utm_source=gemini | G11: El paso de cobro por bloque a cobro por crédito reduce el número promedio de créditos matriculados por estudiante de tiempo completo, lo que impacta negativamente los ingresos por matrícula a menos que la tarifa unitaria por crédito se incremente proporcionalmente. | H11: Sí | I11: Altamente verosímil. Publicación técnica de referencia en gestión institucional y economía de la educación superior en EE. UU. | J11: No | K11: No existe | L11: No existe | M11: No existe | N11: =IF(COUNTA(K11:M11)<2,"",IF(SUMPRODUCT((K11:M11<>"")/COUNTIF(K11:M11,K11:M11&""))=1,"Sí","No")) -> Sí | O11: No existe
A12: A-Q2-02 | B12: A | C12: Q2 | D12: Volkwein, J. F., & Lenth, C. S. (2007). State Policy and Public University Tuition: The Financial Consequences of Tuition Structure Choices. | E12: The Journal of Higher Education | F12: https://www.google.com/search?q=https://doi.org/10.1080/00221546.2007.11772076&utm_source=gemini | G12: El esquema de cobro por crédito favorece la captación de estudiantes no tradicionales y de tiempo parcial, pero desincentiva la graduación a tiempo en estudiantes tradicionales, erosionando la retención a largo plazo. | H12: Sí | I12: Altamente verosímil. Estudio clásico ampliamente citado sobre estructuras tarifarias y financiamiento público en educación superior. | J12: No | K12: No existe | L12: No existe | M12: No existe | N12: =IF(COUNTA(K12:M12)<2,"",IF(SUMPRODUCT((K12:M12<>"")/COUNTIF(K12:M12,K12:M12&""))=1,"Sí","No")) -> Sí | O12: No existe
A13: A-Q2-03 | B13: A | C13: Q2 | D13: DesJardins, S. L., & Bell, A. (2006). Using Economic Models to Estimate the Revenue and Enrollment Effects of Alternative Tuition Structures. | E13: Research in Higher Education | F13: https://www.google.com/search?q=https://doi.org/10.1007/s11162-006-9018-9&utm_source=gemini | G13: Los cambios en la estructura de matrícula generan una reconfiguración de la demanda: el cobro por crédito aumenta la sensibilidad al precio por cada asignatura adicional, afectando el volumen total de créditos vendidos. | H13: Sí | I13: Altamente verosímil. Modelo econométrico riguroso enfocado en elasticidad de la demanda en matriculación universitaria. | J13: Sí | K13: Utilizable | L13: Utilizable | M13: Utilizable | N13: =IF(COUNTA(K13:M13)<2,"",IF(SUMPRODUCT((K13:M13<>"")/COUNTIF(K13:M13,K13:M13&""))=1,"Sí","No")) -> Sí | O13: No existe | Q13: Integrante 2 | R13: 46291
A14: A-Q2-04 | B14: A | C14: Q2 | D14: Baine, N., & Brakora, K. (2024). Tuition Equity and Institutional Revenue: A Study of the Impacts of Block vs. Credit Tuition. | E14: IEEE Transactions on Education / Higher Education Policy Studies | F14: https://www.google.com/search?q=https://doi.org/10.1109/TE.2024.1041234&utm_source=gemini | G14: El cobro en bloque subsidia implÃ­citamente a los estudiantes que toman sobrecargas académicas a expensas de los estudiantes de menor carga, mientras que el cobro por crédito alinea los ingresos directos con el costo marginal de impartir cada curso. | H14: Sí | I14: Requiere verificación rigurosa. Aunque aborda los principios económicos teóricos vigentes sobre equidad tarifaria e ingresos, la atribución formal del DOI específico debe validarse frente a los catálogos finales de la publicación. | J14: No | K14: No existe | L14: No existe | M14: No existe | N14: =IF(COUNTA(K14:M14)<2,"",IF(SUMPRODUCT((K14:M14<>"")/COUNTIF(K14:M14,K14:M14&""))=1,"Sí","No")) -> Sí | O14: No existe
A15: A-Q2-05 | B15: A | C15: Q2 | D15: Gansemer-Topf, A. M., & Schuh, J. H. (2006). Institutional Expenditures and Graduation Rates: Understanding the Functional Expenses That Influence Student Success. | E15: Journal of Student Affairs Research and Practice | F15: https://www.google.com/search?q=https://doi.org/10.2202/1949-6605.1678&utm_source=gemini | G15: Un modelo tarifario que desacelere la progresión crediticia incrementa los costos institucionales indirectos de reclutamiento y retención, afectando el margen neto final de la universidad a mediano plazo. | H15: Sí | I15: Altamente verosímil. Fundamento teórico clave para analizar el impacto indirecto de la duración de la carrera sobre los costos operacionales de la institución. | J15: Sí | K15: Existe pero no dice eso | L15: Existe pero no dice eso | M15: Utilizable | N15: =IF(COUNTA(K15:M15)<2,"",IF(SUMPRODUCT((K15:M15<>"")/COUNTIF(K15:M15,K15:M15&""))=1,"Sí","No")) -> No | O15: Existe pero no dice eso | P15: Journal of Student Affairs Research and Practice, 2006. El estudio real trata sobre cómo el gasto institucional (apoyo académico vs. servicios estudiantiles) afecta la persistencia y graduación — NO sobre estructuras de matrícula ni progresión crediticia. La afirmación de Gemini sobre "modelo tarifario que desacelera la progresión" no está en el estudio. | Q15: Integrante 3 | R15: 46291 | S15: Se confirma "Existe pero no dice eso"
A16: A-Q3-01 | B16: A | C16: Q3 | D16: Acton, R. K. (2021). Effects of flat-rate tuition on student behavior | E16: Economics of Education Review | F16: 10.1016/j.econedurev.2021.102117 | G16: Encuentra que cambiar del cobro estricto por crédito a un esquema de tarifa plana aumenta los créditos matriculados en un 4-5%, reduciendo el ingreso marginal de la institución. Resulta un insumo ideal para fundamentar metodológicamente simulaciones contrafactuales que utilicen archivos históricos de matrícula. | H16: si | I16: El abstract da un aumento en los créditos intentados bajo tarifa plana; no reporta la reducción del ingreso marginal de la institución. Indica impactos en el comportamiento del estudiante, pero la tabla asume el impacto en recaudo. No mide ingresos institucionales | J16: Sí | K16: Utilizable | L16: Utilizable | M16: Utilizable | N16: =IF(COUNTA(K16:M16)<2,"",IF(SUMPRODUCT((K16:M16<>"")/COUNTIF(K16:M16,K16:M16&""))=1,"Sí","No")) -> Sí | O16: Utilizable | P16: “Flat‑rate tuition affects student behavior” (abstract) | Q16: Integrante 3 | R16: 46291 | S16: DOI 10.1016/j.econedurev.2021.102117, artículo en Economics of Education Review.
A17: A-Q3-02 | B17: A | C17: Q3 | D17: Stange, K. (2015). Differential Pricing in Undergraduate Education: Effects on Degree Production by Field | E17: Journal of Policy Analysis and Management | F17: 10.1002/pam.21798 | G17: Demuestra que la estructura de precios afecta directamente la cantidad de créditos tomados, alterando los ingresos institucionales de manera asimétrica. Aporta un marco sólido si se busca evaluar qué tanto hubiera ganado o perdido la universidad comparando estos efectos a nivel de distintas facultades. | H17: Sí (compara tarifa plana uniforme vs. por crédito/campo) | I17: El abstract respalda el efecto en la elección de carrera y créditos por campo debido al precio diferencial. «Alterando los ingresos institucionales de manera asimétrica» no aparece en el abstract. Otro mecanismo (cobro diferencial por programa, no tarifa plana vs crédito estándar). | J17: Sí | K17: Utilizable | L17: Utilizable | M17: Utilizable | N17: =IF(COUNTA(K17:M17)<2,"",IF(SUMPRODUCT((K17:M17<>"")/COUNTIF(K17:M17,K17:M17&""))=1,"Sí","No")) -> Sí | O17: Utilizable | P17: “Differential pricing influences degree production by field” (abstract) | Q17: Integrante 1 | R17: 46292 | S17: DOI 10.1002/pam.21798, artículo en Journal of Policy Analysis and Management.
A18: A-Q3-03 | B18: A | C18: Q3 | D18: Hemelt, S. W., & Marcotte, D. E. (2011). The Impact of Tuition Increases on Enrollment at Public Colleges and Universities | E18: Educational Evaluation and Policy Analysis | F18: 10.3102/0162373711415261 | G18: Evalúa la elasticidad precio-demanda en las universidades, concluyendo que el recaudo no crece de forma directamente proporcional al costo, ya que el estudiante ajusta inmediatamente su carga crediticia para minimizar el impacto financiero. | H18: No (evalúa costos generales frente a carga; es evidencia parcial) | I18: El abstract reporta impactos negativos en la matrícula general (headcount) ante aumentos de precio. Dice que puede haber cambios en el comportamiento, pero no reporta ese resultado de carga crediticia: verificar «ajusta inmediatamente su carga crediticia» en el texto completo. | J18: Sí | K18: Utilizable | L18: Utilizable | M18: Utilizable | N18: =IF(COUNTA(K18:M18)<2,"",IF(SUMPRODUCT((K18:M18<>"")/COUNTIF(K18:M18,K18:M18&""))=1,"Sí","No")) -> Sí | O18: Utilizable | P18: “Tuition increases reduce enrollment at public colleges” (abstract) | Q18: Integrante 3 | R18: 46291 | S18: DOI 10.3102/0162373711415261, artículo en Educational Evaluation and Policy Analysis.
A19: A-Q3-04 | B19: A | C19: Q3 | D19: Kramer, D. A., & Kelchen, R. (2018). The impact of banded tuition policies on student credit loads and institutional revenues | E19: The Journal of Higher Education (estimado) | F19: no disponible | G19: Plantea que los esquemas de tarifa por bloques o bandas elevan los créditos matriculados, pero limitan severamente la capacidad de la universidad de capturar ingresos adicionales por esos créditos extra en comparación con el modelo per-credit. | H19: si | I19: El abstract reporta aumentos en los créditos matriculados debido a políticas de bandas; no reporta métricas exactas de recaudo. «Limitan severamente la capacidad» no aparece en el abstract. No mide ingresos institucionales directamente. | J19: No | K19: No existe | L19: No existe | M19: No existe | N19: =IF(COUNTA(K19:M19)<2,"",IF(SUMPRODUCT((K19:M19<>"")/COUNTIF(K19:M19,K19:M19&""))=1,"Sí","No")) -> Sí | O19: No existe
A20: A-Q3-05 | B20: A | C20: Q3 | D20: Cheslock, J. J. (2005). How pricing strategies affect enrollment and revenues in higher education | E20: Research in Higher Education (estimado) | F20: no disponible | G20: Argumenta que mantener un cobro estricto por crédito produce una alta volatilidad en los ingresos institucionales periodo a periodo, volviendo el recaudo dependiente de las decisiones microeconómicas del estudiante sobre su carga académica. | H20: si | I20: El abstract discute el impacto general de las estrategias de precios. «Alta volatilidad en los ingresos institucionales» no aparece en el abstract (se enfoca en tendencias generales). La tabla asume la dependencia microeconómica que el texto omite. | J20: No | K20: No existe | L20: No existe | M20: No existe | N20: =IF(COUNTA(K20:M20)<2,"",IF(SUMPRODUCT((K20:M20<>"")/COUNTIF(K20:M20,K20:M20&""))=1,"Sí","No")) -> Sí | O20: No existe
A21: B-Q1-01 | B21: B | C21: Q1 | D21: Hemelt, S. W., & Stange, K. M. (2014). Marginal pricing and student investment in higher education. | E21: Journal of Policy Analysis and Management | F21: https://doi.org/10.1002/pam.21891 | G21: Cero precio marginal sobre 12 créditos eleva intentos de créditos en una fracción modesta, con más retiros y menor desempeño. | H21: Sí: precio marginal por crédito (más de 12 créditos) | I21: El abstract da un 7 % de estudiantes que intentan hasta una clase más; no reporta una elasticidad. Indica impactos mínimos en créditos aprobados y avance a tiempo (la tabla lo omite). No mide ingresos institucionales. | J21: Sí | K21: Utilizable | L21: Utilizable | M21: Utilizable | N21: =IF(COUNTA(K21:M21)<2,"",IF(SUMPRODUCT((K21:M21<>"")/COUNTIF(K21:M21,K21:M21&""))=1,"Sí","No")) -> Sí | O21: Utilizable | P21: “Marginal pricing and student investment in higher education” (abstract) | Q21: Integrante 3 | R21: 46291 | S21: DOI 10.1002/pam.21891, artículo en JPAM.
A22: B-Q1-02 | B22: B | C22: Q1 | D22: Hemelt, S. W., & Marcotte, D. E. (2011). The impact of tuition increases on enrollment at public colleges and universities. | E22: Educational Evaluation and Policy Analysis | F22: https://doi.org/10.3102/0162373711415261 | G22: La elasticidad de total enrollment es -0.0958; también cae total credit hours. | H22: Otro mecanismo: nivel de matrícula (no estructura de cobro) | I22: El abstract reporta elasticidad de la matrícula (headcount) de -0,0958. Dice que examinaron credit hours pero no reporta ese resultado: verificar «cae total credit hours» en el texto completo. | J22: Sí | K22: Utilizable | L22: Utilizable | M22: Utilizable | N22: =IF(COUNTA(K22:M22)<2,"",IF(SUMPRODUCT((K22:M22<>"")/COUNTIF(K22:M22,K22:M22&""))=1,"Sí","No")) -> Sí | O22: Utilizable | P22: “Tuition increases reduce enrollment” (abstract) | Q22: Integrante 1 | R22: 46292 | S22: DOI 10.3102/0162373711415261, mismo artículo de Hemelt & Marcotte.
A23: B-Q1-03 | B23: B | C23: Q1 | D23: Ward, J., & Corral, D. (2022). Resetting prices: Estimating the effect of tuition reset policies on institutional finances and enrollment. | E23: Research in Higher Education | F23: https://doi.org/10.1007/s11162-022-09723-6 | G23: Net tuition revenue por FTE permanece estable; escasa evidencia de gains de enrollment de largo plazo. | H23: Otro mecanismo: reducción del precio de lista (tuition reset) | I23: «Por FTE» no aparece en el abstract (dice que el ingreso neto por matrícula parece no relacionado con los resets). Un reset es un recorte del precio de lista, no un cambio de estructura de cobro. | J23: Sí | K23: Utilizable | L23: Utilizable | M23: Utilizable | N23: =IF(COUNTA(K23:M23)<2,"",IF(SUMPRODUCT((K23:M23<>"")/COUNTIF(K23:M23,K23:M23&""))=1,"Sí","No")) -> Sí | O23: Utilizable | P23: “Tuition reset policies affect finances and enrollment” (abstract) | Q23: Integrante 2 | R23: 46291 | S23: DOI 10.1007/s11162-022-09723-6, artículo en Research in Higher Education.
A24: B-Q1-04 | B24: B | C24: Q1 | D24: Curs, B. R., & Singell, L. D. (2010). Aim high or go low? Pricing strategies and enrollment effects when the net price elasticity varies with need and ability. | E24: The Journal of Higher Education | F24: https://doi.org/10.1080/00221546.2010.11779063 | G24: Estrategias high tuition/high aid pueden reducir tuition revenue. | H24: Otro mecanismo: alta matrícula/alta ayuda | I24: El abstract respalda el resultado (simulación con datos de aspirantes a una universidad pública grande). Otro mecanismo y una sola institución. | J24: Sí | K24: Utilizable | L24: Existe pero no dice eso | M24: Existe pero no dice eso | N24: =IF(COUNTA(K24:M24)<2,"",IF(SUMPRODUCT((K24:M24<>"")/COUNTIF(K24:M24,K24:M24&""))=1,"Sí","No")) -> No | O24: Utilizable | P24: Journal of Higher Education, 81(4), pp. 515–543, abstract: confirma que HH/HA reduce el ingreso por matrícula. | Q24: Integrante 1 | R24: 46292 | S24: Si es un tema de relevancia para la pregunta, no de si la afirmación es correcta. Por la definición de las categorías, si el texto sí respalda la afirmación, debería ser "Utilizable", aunque también anoten en Notas que es de un mecanismo distinto al que estudian.
A25: B-Q1-05 | B25: B | C25: Q1 | D25: Johnson, N. (2016). Aligning student and institution incentives in higher education finance. | E25: (sin revista ni DOI en el CSV) | F25: https://consensus.app/papers/aligning-student-and-institution-incentives-in-higher-johnson/24ff620a82e959729c48e2ccce24d3e7/ | G25: Los credit hours son un driver primario de revenue institucional. | H25: Comentario/informe, no revisado por pares (relaciona créditos e ingresos) | I25: Sin revista ni DOI; solo enlace de Consensus. El abstract lo afirma, pero es una afirmación, no evidencia empírica. Localizar la fuente original. | J25: No | K25: No existe | L25: No existe | M25: No existe | N25: =IF(COUNTA(K25:M25)<2,"",IF(SUMPRODUCT((K25:M25<>"")/COUNTIF(K25:M25,K25:M25&""))=1,"Sí","No")) -> Sí | O25: No existe
A26: B-Q2-01 | B26: B | C26: Q2 | D26: Hemelt, S. W., & Stange, K. M. (s.f.), "Marginal Pricing and Student Investment in Higher Education" | E26: Journal of Policy Analysis and Management (EE. UU.) | F26: https://consensus.app/papers/marginal-pricing-and-student-investment-in-higher-hemelt-stange/c97a0c599b575124b84285f3838460df/ | G26: Reducir el precio marginal por crédito a cero induce a un 7% de estudiantes a intentar una clase adicional (3 créditos), pero eleva abandonos y reduce rendimiento académico, con impacto mínimo en créditos completados a tiempo | H26: Sí | I26: Coincide plenamente con el abstract; compara directamente precio marginal por crédito frente a precio marginal cero | J26: Sí | K26: Utilizable | L26: Utilizable | M26: Utilizable | N26: =IF(COUNTA(K26:M26)<2,"",IF(SUMPRODUCT((K26:M26<>"")/COUNTIF(K26:M26,K26:M26&""))=1,"Sí","No")) -> Sí | O26: Utilizable | P26: “Marginal pricing and student investment” (abstract) | Q26: Integrante 3 | R26: 46291 | S26: DOI 10.1002/pam.21891, JPAM.
A27: B-Q2-02 | B27: B | C27: Q2 | D27: Baine, N., & Brakora, K. F. (2024), "Tuition Equity: A Study of the Disparate Impacts of Block Tuition" | E27: 2024 ASEE Annual Conference & Exposition Proceedings (EE. UU.) | F27: https://consensus.app/papers/tuition-equity-a-study-of-the-disparate-impacts-of-block-baine-brakora/156d9ccdd844583f9ef7cc51e4cceced/ | G27: La matrícula en bloque (12-15 créditos a costo de 12 por crédito) equivale a un descuento de hasta 20%, pero penaliza a estudiantes de bajos ingresos o ingeniería que pagan más por crédito al no alcanzar los 15 créditos | H27: Sí | I27: Coincide con el texto y abstract; evalúa la inequidad del cobro por bloque frente a la tasa por crédito horario | J27: Sí | K27: Utilizable | L27: Utilizable | M27: Utilizable | N27: =IF(COUNTA(K27:M27)<2,"",IF(SUMPRODUCT((K27:M27<>"")/COUNTIF(K27:M27,K27:M27&""))=1,"Sí","No")) -> Sí | O27: Utilizable | P27: Abstract, p. 1 (20% de descuento); sección Results (7,1% transferidos de ingeniería vs. 14% no transferidos). PDF completo: peer.asee.org/48180.pdf | Q27: Integrante 1 | R27: 46292 | S27: DOI 10.18260/1-2--48180, ASEE.
A28: B-Q2-03 | B28: B | C28: Q2 | D28: Keenan, C., Chhatwal, G. S., & Wang, J. (2015), "A Study of the Effects and Policy Implications of Flat Rate Tuition" | E28: International Journal of Research in Education Methodology (EE. UU.) | F28: https://consensus.app/papers/a-study-of-the-effects-and-policy-implications-of-flat-rate-keenan-chhatwal/29f850483b125d2c9f4e35706a9af81e/ | G28: Los estudiantes responden favorablemente a la tarifa plana aumentando su carga académica semestral y mejorando el progreso académico respecto al esquema estricto por crédito | H28: Sí | I28: Coincide plenamente con el abstract y la introducción del artículo | J28: Sí | K28: Existe pero no dice eso | L28: Existe pero no dice eso | M28: Existe pero no dice eso | N28: =IF(COUNTA(K28:M28)<2,"",IF(SUMPRODUCT((K28:M28<>"")/COUNTIF(K28:M28,K28:M28&""))=1,"Sí","No")) -> Sí | O28: Existe pero no dice eso | P28: International Journal of Research in Education Methodology, 6(2), pp. 837-849 (2014, no 2015). No pude acceder al texto completo para verificar la cifra exacta del "130% de aumento en overload" — requiere que alguien del equipo abra el PDF y confirme esa cifra específica antes de darla por buena. | Q28: Integrante 3 | R28: 46291
A29: B-Q2-04 | B29: B | C29: Q2 | D29: Hemelt, S. W., & Marcotte, D. E. (2011), "The Impact of Tuition Increases on Enrollment at Public Colleges and Universities" | E29: Educational Evaluation and Policy Analysis (EE. UU.) | F29: https://consensus.app/papers/the-impact-of-tuition-increases-on-enrollment-at-public-hemelt-marcotte/a90095cad36b584488692543d9d54236/ | G29: La elasticidad precio de la matrícula es de −0.0958 globalmente; el ajuste marginal de créditos ante aumentos de matrícula tiende a ser mayor en instituciones que cobran por hora-crédito que con tarifa plana semestral | H29: Sí | I29: Coincide con los hallazgos reportados; analiza la respuesta marginal de créditos según el esquema de cobro | J29: Sí | K29: Utilizable | L29: Utilizable | M29: Utilizable | N29: =IF(COUNTA(K29:M29)<2,"",IF(SUMPRODUCT((K29:M29<>"")/COUNTIF(K29:M29,K29:M29&""))=1,"Sí","No")) -> Sí | O29: Utilizable | P29: “Tuition increases reduce enrollment” (abstract) | Q29: Integrante 3 | R29: 46291 | S29: DOI 10.3102/0162373711415261, EEPA.
A30: B-Q2-05 | B30: B | C30: Q2 | D30: Johnson, N. (2016), "Aligning Student And Institution Incentives In Higher Education Finance" | E30: Informe de política institucional (EE. UU.) | F30: https://consensus.app/papers/aligning-student-and-institution-incentives-in-higher-johnson/24ff620a82e959729c48e2ccce24d3e7/ | G30: El modelo institucional tradicional de "dinero por crédito" incentiva a las universidades a incrementar ingresos vendiendo más horas-crédito por estudiante o subiendo el precio unitario por crédito | H30: Sí | I30: Coincide plenamente con el abstract; analiza la dependencia institucional de los ingresos por crédito | J30: No | K30: No existe | L30: No existe | M30: No existe | N30: =IF(COUNTA(K30:M30)<2,"",IF(SUMPRODUCT((K30:M30<>"")/COUNTIF(K30:M30,K30:M30&""))=1,"Sí","No")) -> Sí | O30: No existe
A31: B-Q3-01 | B31: B | C31: Q3 | D31: Steven W. Hemelt, Kevin M. Stange, 2014, Marginal Pricing and Student Investment in Higher Education | E31: Journal of Policy Analysis and Management | F31: 10.1002/pam.21891 | G31: En universidades públicas de Michigan, reducir a cero el precio marginal de créditos adicionales sobre 12 indujo a una fracción modesta de estudiantes a intentar hasta una materia adicional, pero también elevó retiros y redujo el desempeño; los efectos sobre créditos aprobados y avance “a tiempo” fueron pequeños o imprecisos, por lo que el estudio sirve sobre todo para la rama estructura de cobro → créditos intentados, no para inferir directamente recaudo institucional | H31: Si | I31: Coincide con el abstract real del artículo. | J31: Sí | K31: Utilizable | L31: Utilizable | M31: Utilizable | N31: =IF(COUNTA(K31:M31)<2,"",IF(SUMPRODUCT((K31:M31<>"")/COUNTIF(K31:M31,K31:M31&""))=1,"Sí","No")) -> Sí | O31: Utilizable | P31: “Marginal pricing and student investment” (abstract) | Q31: Integrante 3 | R31: 46291 | S31: DOI 10.1002/pam.21891, JPAM.
A32: B-Q3-02 | B32: B | C32: Q3 | D32: C. Keenan, Gurprit S. Chhatwal, Jinchang Wang, 2015, A Study of the Effects and Policy Implications of Flat Rate Tuition | E32: International Journal of Research in Education Methodology | F32: 10.24297/ijrem.v6i2.3879 | G32: En un college público de cuatro años, la tarifa plana se compara explícitamente con cobro por crédito y se asocia con mayor carga matriculada: los créditos “overload” aumentaron casi 130% en cinco años y la proporción que toma 17+ créditos pasó de ~18% a 35%; además, la caída en retiros contradice la objeción de que la tarifa plana solo infla matrícula tentativa. No reporta un efecto directo estimado sobre recaudo institucional | H32: Si | I32: Coincide con el abstract y con extractos de texto completo disponibles. | J32: Sí | K32: Existe pero no dice eso | L32: Existe pero no dice eso | M32: Existe pero no dice eso | N32: =IF(COUNTA(K32:M32)<2,"",IF(SUMPRODUCT((K32:M32<>"")/COUNTIF(K32:M32,K32:M32&""))=1,"Sí","No")) -> Sí | O32: Existe pero no dice eso | P32: International Journal of Research in Education Methodology, 6(2), pp. 837-849 (2014, no 2015). No pude acceder al texto completo para verificar la cifra exacta del "130% de aumento en overload" — requiere que alguien del equipo abra el PDF y confirme esa cifra específica antes de darla por buena. | Q32: Integrante 3 | R32: 46291
A33: B-Q3-03 | B33: B | C33: Q3 | D33: Nicholas Baine, Karl F. Brakora, 2024, Tuition Equity: A Study of the Disparate Impacts of Block Tuition | E33: 2024 ASEE Annual Conference & Exposition Proceedings | F33: 10.18260/1-2--48180 | G33: El estudio no estima causalmente cambio de comportamiento, pero sí operacionaliza la comparación bloque vs. por crédito aplicando ambas tarifas a historiales reales de 32,454 graduados; documenta que un bloque 12–15 equivalente al precio de 12 créditos genera un descuento de hasta 20% y crea incentivos a matricularse cerca de 15 créditos, con menor beneficio efectivo para transferidos, estudiantes Pell y estudiantes de color. Es útil para simular ingresos contrafactuales y distribución del subsidio implícito, más que para medir recaudo observado | H33: Si | I33: La afirmación mezcla resultados confirmados en abstract/extractos con una inferencia analítica prudente sobre su utilidad para simulación; no verifica recaudo observado. | J33: Sí | K33: Utilizable | L33: Utilizable | M33: Utilizable | N33: =IF(COUNTA(K33:M33)<2,"",IF(SUMPRODUCT((K33:M33<>"")/COUNTIF(K33:M33,K33:M33&""))=1,"Sí","No")) -> Sí | O33: Utilizable | P33: Abstract, p. 1 (20% de descuento); sección Results (7,1% transferidos de ingeniería vs. 14% no transferidos). PDF completo: peer.asee.org/48180.pdf | Q33: Integrante 1 | R33: 46292 | S33: DOI 10.18260/1-2--48180, ASEE.
A34: B-Q3-04 | B34: B | C34: Q3 | D34: C. W. DeMoranville, P. O'Donnell, 2001, Price Elasticity of Per-Credit-Hour Tuition Charges and the Effects on Four-Year Graduation Rates | E34: Journal of Marketing for Higher Education | F34: 10.1300/j050v11n04_03 | G34: El estudio examina un cambio hacia una escala deslizante por número de créditos y concluye que ese esquema no aumentó la graduación en cuatro años. Aporta evidencia parcial para tu marco porque sí trata cobro por crédito, pero en los extractos disponibles no confirma directamente efectos sobre créditos matriculados ni sobre recaudo institucional | H34: Si | I34: Coincide con el abstract real del artículo, pero la conexión con carga crediticia o recaudo es una limitación explícita de la evidencia disponible aquí. | J34: Sí | K34: Utilizable | L34: Utilizable | M34: Utilizable | N34: =IF(COUNTA(K34:M34)<2,"",IF(SUMPRODUCT((K34:M34<>"")/COUNTIF(K34:M34,K34:M34&""))=1,"Sí","No")) -> Sí | O34: Utilizable | P34: “Per‑credit‑hour tuition charges did not increase graduation rates” (abstract) | Q34: Integrante 3 | R34: 46291 | S34: DOI 10.1300/j050v11n04_03, Journal of Marketing for Higher Education.
A35: B-Q3-05 | B35: B | C35: Q3 | D35: George A. Chressanthis, 1986, The impacts of tuition rate changes on college undergraduate headcounts and credit hours over time -- a case study | E35: Economics of Education Review | F35: 10.1016/0272-7757(86)90013-0 | G35: El estudio estima cómo cambios en tasas de matrícula afectan headcount y credit hours, y encuentra que la conducta estudiantil sigue la ley de demanda y varía por nivel académico. Es relevante para sensibilidad de créditos frente al precio, pero no permite confirmar, con la información disponible, una comparación directa entre cobro por crédito estricto y tarifa plana/bloques; por eso su valor aquí es contextual y parcial | H35: No; trata cambios en tasas de matrícula y horas-crédito, no una comparación directa verificada per-credit vs. flat-rate | I35: Coincide con el abstract real del artículo; la clasificación como evidencia parcial refleja la falta de verificación de un contraste directo entre esquemas. | J35: Sí | K35: Utilizable | L35: Utilizable | M35: Utilizable | N35: =IF(COUNTA(K35:M35)<2,"",IF(SUMPRODUCT((K35:M35<>"")/COUNTIF(K35:M35,K35:M35&""))=1,"Sí","No")) -> Sí | O35: Utilizable | P35: “Tuition rate changes impact headcounts and credit hours” (p. 205, abstract) | Q35: Integrante 1 | R35: 46292 | S35: DOI 10.1016/0272-7757(86)90013-0, Economics of Education Review.
A36: C-Q1-01 | B36: C | C36: Q1 | D36: Curs, B. R., & Singell, L. D. Jr. (2009). Aim High or Go Low? Pricing Strategies and Enrollment Effects when the Net Price Elasticity Varies with Need and Ability. Manuscrito, University of Oregon. | E36: Manuscrito (no publicado en el documento adjunto) | F36: No aparece en el documento adjunto | G36: Elasticidad del precio neto: −0,87 residentes, −1,20 no residentes; una política low tuition/low aid aumentaría el ingreso neto en ~US$601 por residente y ~US$339 por no residente. | H36: No directamente: estudia precio neto y ayuda financiera (HH/LL), no compara per-credit vs. plateau como tratamiento. | I36: Cruce con B: en tu tratamiento B, Consensus dio "Curs, B. R., & Singell, L. D. (2010)" en The Journal of Higher Education, con DOI 10.1080/00221546.2010.11779063. Aquí en C aparece como manuscrito de 2009 sin DOI. Es probable que sea la misma investigación (working paper → publicación), pero hay que confirmarlo: revisen si el DOI de B corresponde a este mismo estudio. | J36: No | K36: Utilizable | L36: Utilizable | M36: No existe | N36: =IF(COUNTA(K36:M36)<2,"",IF(SUMPRODUCT((K36:M36<>"")/COUNTIF(K36:M36,K36:M36&""))=1,"Sí","No")) -> No | O36: Utilizable | P36: Journal of Higher Education, 81(4), pp. 515–543 (versión publicada del manuscrito de 2009 de Curs & Singell) | Q36: Integrante 2 | R36: 46291 | S36: confirmado — C-Q1-01 y B-Q1-04 son la misma investigación en dos versiones (manuscrito vs. publicación).
A37: C-Q1-02 | B37: C | C37: Q1 | D37: Baine, N. A., & Brakora, K. (2024). Tuition Equity: A Study of the Disparate Impacts of Block Tuition. ASEE, Paper ID #44145. | E37: American Society for Engineering Education (ASEE) | F37: No aparece en el documento adjunto | G37: Block tuition en GVSU da un descuento de hasta 20% (paga 12 de 15 créditos); estudiantes de ingeniería transferidos tienen descuento efectivo ~7,1% vs. ~14% para no transferidos. | H37: Parcial: estudia block/plateau tuition y lo usa como referencia de cálculo frente al cobro por crédito, pero no estima el revenue institucional bajo ambos escenarios. | I37: Mismo estudio que B-Q1 (extra): es el mismo Baine & Brakora "Disparate Impacts of Block Tuition" que ya tienes en el bloque de extras de B. Comparen si el "¿Trata cobro por crédito?" y el resumen coinciden entre lo que dijo Consensus y lo que dice el sistema anclado — es un buen punto para la memoria. | J37: No | K37: Utilizable | L37: Utilizable | M37: Utilizable | N37: =IF(COUNTA(K37:M37)<2,"",IF(SUMPRODUCT((K37:M37<>"")/COUNTIF(K37:M37,K37:M37&""))=1,"Sí","No")) -> Sí | O37: Utilizable | P37: Abstract, p. 1 (20% de descuento); sección Results (7,1% transferidos de ingeniería vs. 14% no transferidos). PDF completo: peer.asee.org/48180.pdf | Q37: Integrante 1 | R37: 46292 | S37: DOI 10.18260/1-2--48180, ASEE.
A38: C-Q1-03 | B38: C | C38: Q1 | N38: =IF(COUNTA(K38:M38)<2,"",IF(SUMPRODUCT((K38:M38<>"")/COUNTIF(K38:M38,K38:M38&""))=1,"Sí","No"))
A39: C-Q1-04 | B39: C | C39: Q1 | N39: =IF(COUNTA(K39:M39)<2,"",IF(SUMPRODUCT((K39:M39<>"")/COUNTIF(K39:M39,K39:M39&""))=1,"Sí","No"))
A40: C-Q1-05 | B40: C | C40: Q1 | N40: =IF(COUNTA(K40:M40)<2,"",IF(SUMPRODUCT((K40:M40<>"")/COUNTIF(K40:M40,K40:M40&""))=1,"Sí","No"))
A41: C-Q2-01 | B41: C | C41: Q2 | D41: Gansemer-Topf, A., Orazem, P. F., & Wohlgemuth, D. R. (2021). Do liberal arts colleges maximize profit? | E41: Southern Economic Journal | F41: https://doi.org/10.1002/soej.12521 | G41: 405 liberal arts colleges. Net tuition varía más idiosincráticamente que enrollment; ingresos y matrícula están estrechamente ligados en undergraduate institutions. | H41: Otro mecanismo: matrícula que maximiza el ingreso neto | I41: «405 colleges» y el resultado de la tabla NO aparecen en el abstract del CSV. El enlace de la tabla apunta a una nota de NACUBO, no al artículo; el DOI del CSV es otro. Verificar en el texto completo. | J41: Sí | K41: Utilizable | L41: Utilizable | M41: Utilizable | N41: =IF(COUNTA(K41:M41)<2,"",IF(SUMPRODUCT((K41:M41<>"")/COUNTIF(K41:M41,K41:M41&""))=1,"Sí","No")) -> Sí | O41: Utilizable | P41: “Do liberal arts colleges maximize profit?” (abstract) | Q41: Integrante 2 | R41: 46291 | S41: DOI 10.1002/soej.12521, Southern Economic Journal.
...

Sheet Conteo
A1: Conteo por tratamiento (calculado a partir de «Referencias» · Clasificación final, las 3 consultas juntas)
A3: Nivel de confianza | B3: 0.95 | C3: Supuesto elegido por nosotros (valor usual); cámbialo si tu diseño usa otro.
A4: α | B4: =1-B3 -> 0.05
A5: z | B5: =NORMSINV(1-B4/2) -> 1.959964
A8: Tratamiento | B8: Descripción | C8: n clasificadas | D8: Utilizable | E8: Existe pero no dice eso | F8: No existe | G8: Chequeo | H8: Proporción utilizable | I8: Wilson · inferior | J8: Wilson · superior | K8: Clopper-Pearson · inferior | L8: Clopper-Pearson · superior
A9: A | B9: Chat sin fuentes ni navegación (control) | C9: =COUNTIFS(Referencias!$B$6:$B$50,$A9,Referencias!$O$6:$O$50,"<>") -> 15 | D9: =COUNTIFS(Referencias!$B$6:$B$50,$A9,Referencias!$O$6:$O$50,D$8) -> 4 | E9: =COUNTIFS(Referencias!$B$6:$B$50,$A9,Referencias!$O$6:$O$50,E$8) -> 2 | F9: =COUNTIFS(Referencias!$B$6:$B$50,$A9,Referencias!$O$6:$O$50,F$8) -> 9 | G9: =IF(C9=D9+E9+F9,"OK","Revisar") -> OK | H9: =IF($C9=0,"",D9/$C9) -> 0.26666667 | I9: =IF($C9=0,"",(H9+$B$5^2/(2*$C9)-$B$5*SQRT(H9*(1-H9)/$C9+$B$5^2/(4*$C9^2)))/(1+$B$5^2/$C9)) -> 0.10897453 | J9: =IF($C9=0,"",(H9+$B$5^2/(2*$C9)+$B$5*SQRT(H9*(1-H9)/$C9+$B$5^2/(4*$C9^2)))/(1+$B$5^2/$C9)) -> 0.51950434 | K9: =IF($C9=0,"",IF(D9=0,0,BETAINV($B$4/2,D9,$C9-D9+1))) -> 0.077871546 | L9: =IF($C9=0,"",IF(D9=$C9,1,BETAINV(1-$B$4/2,D9+1,$C9-D9))) -> 0.55100324
A10: B | B10: Buscador conectado a bases bibliográficas | C10: =COUNTIFS(Referencias!$B$6:$B$50,$A10,Referencias!$O$6:$O$50,"<>") -> 15 | D10: =COUNTIFS(Referencias!$B$6:$B$50,$A10,Referencias!$O$6:$O$50,D$8) -> 11 | E10: =COUNTIFS(Referencias!$B$6:$B$50,$A10,Referencias!$O$6:$O$50,E$8) -> 2 | F10: =COUNTIFS(Referencias!$B$6:$B$50,$A10,Referencias!$O$6:$O$50,F$8) -> 2 | G10: =IF(C10=D10+E10+F10,"OK","Revisar") -> OK | H10: =IF($C10=0,"",D10/$C10) -> 0.73333333 | I10: =IF($C10=0,"",(H10+$B$5^2/(2*$C10)-$B$5*SQRT(H10*(1-H10)/$C10+$B$5^2/(4*$C10^2)))/(1+$B$5^2/$C10)) -> 0.48049566 | J10: =IF($C10=0,"",(H10+$B$5^2/(2*$C10)+$B$5*SQRT(H10*(1-H10)/$C10+$B$5^2/(4*$C10^2)))/(1+$B$5^2/$C10)) -> 0.89102547 | K10: =IF($C10=0,"",IF(D10=0,0,BETAINV($B$4/2,D10,$C10-D10+1))) -> 0.44899676 | L10: =IF($C10=0,"",IF(D10=$C10,1,BETAINV(1-$B$4/2,D10+1,$C10-D10))) -> 0.92212845
A11: C | B11: Contexto cerrado con sus propios PDF | C11: =COUNTIFS(Referencias!$B$6:$B$50,$A11,Referencias!$O$6:$O$50,"<>") -> 7 | D11: =COUNTIFS(Referencias!$B$6:$B$50,$A11,Referencias!$O$6:$O$50,D$8) -> 7 | E11: =COUNTIFS(Referencias!$B$6:$B$50,$A11,Referencias!$O$6:$O$50,E$8) -> 0 | F11: =COUNTIFS(Referencias!$B$6:$B$50,$A11,Referencias!$O$6:$O$50,F$8) -> 0 | G11: =IF(C11=D11+E11+F11,"OK","Revisar") -> OK | H11: =IF($C11=0,"",D11/$C11) -> 1 | I11: =IF($C11=0,"",(H11+$B$5^2/(2*$C11)-$B$5*SQRT(H11*(1-H11)/$C11+$B$5^2/(4*$C11^2)))/(1+$B$5^2/$C11)) -> 0.64566956 | J11: =IF($C11=0,"",(H11+$B$5^2/(2*$C11)+$B$5*SQRT(H11*(1-H11)/$C11+$B$5^2/(4*$C11^2)))/(1+$B$5^2/$C11)) -> 1 | K11: =IF($C11=0,"",IF(D11=0,0,BETAINV($B$4/2,D11,$C11-D11+1))) -> 0.5903836 | L11: =IF($C11=0,"",IF(D11=$C11,1,BETAINV(1-$B$4/2,D11+1,$C11-D11))) -> 1
A12: Con pocas referencias por tratamiento los intervalos son anchos: dilo en la interpretación. Wilson es una opción usual con n pequeño; Clopper-Pearson (exacto) es más conservador. Elige uno y justifícalo en la memoria.
A15: Desacuerdo de clasificación (entre los 3 integrantes, las 3 consultas juntas)
A16: Tratamiento | B16: Referencias con 2 o más clasificaciones | C16: No coincidieron | D16: % de desacuerdo | E16: De esas, involucran «Existe pero no dice eso»
A17: A | B17: =COUNTIFS(Referencias!$B$6:$B$50,$A17,Referencias!$N$6:$N$50,"Sí")+COUNTIFS(Referencias!$B$6:$B$50,$A17,Referencias!$N$6:$N$50,"No") -> 15 | C17: =COUNTIFS(Referencias!$B$6:$B$50,$A17,Referencias!$N$6:$N$50,"No") -> 2 | D17: =IF(B17=0,"",C17/B17) -> 0.13333333 | E17: =SUMPRODUCT((Referencias!$B$6:$B$50=$A17)*(Referencias!$N$6:$N$50="No")*(((Referencias!$K$6:$K$50=$E$8)+(Referencias!$L$6:$L$50=$E$8)+(Referencias!$M$6:$M$50=$E$8))>0)) -> 2
A18: B | B18: =COUNTIFS(Referencias!$B$6:$B$50,$A18,Referencias!$N$6:$N$50,"Sí")+COUNTIFS(Referencias!$B$6:$B$50,$A18,Referencias!$N$6:$N$50,"No") -> 15 | C18: =COUNTIFS(Referencias!$B$6:$B$50,$A18,Referencias!$N$6:$N$50,"No") -> 1 | D18: =IF(B18=0,"",C18/B18) -> 0.066666667 | E18: =SUMPRODUCT((Referencias!$B$6:$B$50=$A18)*(Referencias!$N$6:$N$50="No")*(((Referencias!$K$6:$K$50=$E$8)+(Referencias!$L$6:$L$50=$E$8)+(Referencias!$M$6:$M$50=$E$8))>0)) -> 1
A19: C | B19: =COUNTIFS(Referencias!$B$6:$B$50,$A19,Referencias!$N$6:$N$50,"Sí")+COUNTIFS(Referencias!$B$6:$B$50,$A19,Referencias!$N$6:$N$50,"No") -> 7 | C19: =COUNTIFS(Referencias!$B$6:$B$50,$A19,Referencias!$N$6:$N$50,"No") -> 1 | D19: =IF(B19=0,"",C19/B19) -> 0.14285714 | E19: =SUMPRODUCT((Referencias!$B$6:$B$50=$A19)*(Referencias!$N$6:$N$50="No")*(((Referencias!$K$6:$K$50=$E$8)+(Referencias!$L$6:$L$50=$E$8)+(Referencias!$M$6:$M$50=$E$8))>0)) -> 0
A20: Total | B20: =SUM(B17:B19) -> 37 | C20: =SUM(C17:C19) -> 4 | D20: =IF(B20=0,"",C20/B20) -> 0.10810811 | E20: =SUM(E17:E19) -> 3
A21: El enunciado pide reportar en cuántas no coincidió la clasificación y por qué. La categoría intermedia suele concentrar el desacuerdo: la última columna lo mide.
A24: Acuerdo entre integrantes (opcional) · pares de columnas
A25: Par | B25: Clasificadas por ambos | C25: Acuerdo observado (po) | D25: Kappa aprox.
A26: Integrante 1 vs. 2 | B26: =COUNTIFS(Referencias!$K$6:$K$50,"<>",Referencias!$L$6:$L$50,"<>") -> 37 | C26: =IF(B26=0,"",(COUNTIFS(Referencias!$K$6:$K$50,$D$8,Referencias!$L$6:$L$50,$D$8)+COUNTIFS(Referencias!$K$6:$K$50,$E$8,Referencias!$L$6:$L$50,$E$8)+COUNTIFS(Referencias!$K$6:$K$50,$F$8,Referencias!$L$6:$L$50,$F$8))/B26) -> 0.97297297 | D26: =IF(B26=0,"",IF(1-((COUNTIFS(Referencias!$K$6:$K$50,$D$8)*COUNTIFS(Referencias!$L$6:$L$50,$D$8)+COUNTIFS(Referencias!$K$6:$K$50,$E$8)*COUNTIFS(Referencias!$L$6:$L$50,$E$8)+COUNTIFS(Referencias!$K$6:$K$50,$F$8)*COUNTIFS(Referencias!$L$6:$L$50,$F$8))/B26^2)=0,"",(C26-((COUNTIFS(Referencias!$K$6:$K$50,$D$8)*COUNTIFS(Referencias!$L$6:$L$50,$D$8)+COUNTIFS(Referencias!$K$6:$K$50,$E$8)*COUNTIFS(Referencias!$L$6:$L$50,$E$8)+COUNTIFS(Referencias!$K$6:$K$50,$F$8)*COUNTIFS(Referencias!$L$6:$L$50,$F$8))/B26^2))/(1-((COUNTIFS(Referencias!$K$6:$K$50,$D$8)*COUNTIFS(Referencias!$L$6:$L$50,$D$8)+COUNTIFS(Referencias!$K$6:$K$50,$E$8)*COUNTIFS(Referencias!$L$6:$L$50,$E$8)+COUNTIFS(Referencias!$K$6:$K$50,$F$8)*COUNTIFS(Referencias!$L$6:$L$50,$F$8))/B26^2)))) -> 0.94832402
A27: Integrante 1 vs. 3 | B27: =COUNTIFS(Referencias!$K$6:$K$50,"<>",Referencias!$M$6:$M$50,"<>") -> 37 | C27: =IF(B27=0,"",(COUNTIFS(Referencias!$K$6:$K$50,$D$8,Referencias!$M$6:$M$50,$D$8)+COUNTIFS(Referencias!$K$6:$K$50,$E$8,Referencias!$M$6:$M$50,$E$8)+COUNTIFS(Referencias!$K$6:$K$50,$F$8,Referencias!$M$6:$M$50,$F$8))/B27) -> 0.89189189 | D27: =IF(B27=0,"",IF(1-((COUNTIFS(Referencias!$K$6:$K$50,$D$8)*COUNTIFS(Referencias!$M$6:$M$50,$D$8)+COUNTIFS(Referencias!$K$6:$K$50,$E$8)*COUNTIFS(Referencias!$M$6:$M$50,$E$8)+COUNTIFS(Referencias!$K$6:$K$50,$F$8)*COUNTIFS(Referencias!$M$6:$M$50,$F$8))/B27^2)=0,"",(C27-((COUNTIFS(Referencias!$K$6:$K$50,$D$8)*COUNTIFS(Referencias!$M$6:$M$50,$D$8)+COUNTIFS(Referencias!$K$6:$K$50,$E$8)*COUNTIFS(Referencias!$M$6:$M$50,$E$8)+COUNTIFS(Referencias!$K$6:$K$50,$F$8)*COUNTIFS(Referencias!$M$6:$M$50,$F$8))/B27^2))/(1-((COUNTIFS(Referencias!$K$6:$K$50,$D$8)*COUNTIFS(Referencias!$M$6:$M$50,$D$8)+COUNTIFS(Referencias!$K$6:$K$50,$E$8)*COUNTIFS(Referencias!$M$6:$M$50,$E$8)+COUNTIFS(Referencias!$K$6:$K$50,$F$8)*COUNTIFS(Referencias!$M$6:$M$50,$F$8))/B27^2)))) -> 0.78581766
A28: Integrante 2 vs. 3 | B28: =COUNTIFS(Referencias!$L$6:$L$50,"<>",Referencias!$M$6:$M$50,"<>") -> 37 | C28: =IF(B28=0,"",(COUNTIFS(Referencias!$L$6:$L$50,$D$8,Referencias!$M$6:$M$50,$D$8)+COUNTIFS(Referencias!$L$6:$L$50,$E$8,Referencias!$M$6:$M$50,$E$8)+COUNTIFS(Referencias!$L$6:$L$50,$F$8,Referencias!$M$6:$M$50,$F$8))/B28) -> 0.91891892 | D28: =IF(B28=0,"",IF(1-((COUNTIFS(Referencias!$L$6:$L$50,$D$8)*COUNTIFS(Referencias!$M$6:$M$50,$D$8)+COUNTIFS(Referencias!$L$6:$L$50,$E$8)*COUNTIFS(Referencias!$M$6:$M$50,$E$8)+COUNTIFS(Referencias!$L$6:$L$50,$F$8)*COUNTIFS(Referencias!$M$6:$M$50,$F$8))/B28^2)=0,"",(C28-((COUNTIFS(Referencias!$L$6:$L$50,$D$8)*COUNTIFS(Referencias!$M$6:$M$50,$D$8)+COUNTIFS(Referencias!$L$6:$L$50,$E$8)*COUNTIFS(Referencias!$M$6:$M$50,$E$8)+COUNTIFS(Referencias!$L$6:$L$50,$F$8)*COUNTIFS(Referencias!$M$6:$M$50,$F$8))/B28^2))/(1-((COUNTIFS(Referencias!$L$6:$L$50,$D$8)*COUNTIFS(Referencias!$M$6:$M$50,$D$8)+COUNTIFS(Referencias!$L$6:$L$50,$E$8)*COUNTIFS(Referencias!$M$6:$M$50,$E$8)+COUNTIFS(Referencias!$L$6:$L$50,$F$8)*COUNTIFS(Referencias!$M$6:$M$50,$F$8))/B28^2)))) -> 0.84410112
A30: Con n pequeño interprétalo con cautela; lo que exige el enunciado es el conteo de la sección anterior.

Sheet Registro
A1: Registro del experimento (9 filas: 3 consultas × 3 tratamientos)
A2: Cada integrante llena las 3 filas de su propia consulta (una por tratamiento): herramienta y versión, fecha y el prompt exacto.
A4: Consulta | B4: Integrante | C4: Tratamiento | D4: Herramienta y versión | E4: Fecha de la consulta | F4: Prompt o consulta exacta (pégalo sin editar) | G4: Notas
A5: Q1 | B5: Integrante 1 ROA | C5: A | D5: Gemini | E5: 46289 | F5: Realiza una revisión de literatura científica sobre la siguiente pregunta de investigación: ¿Qué efectos tiene el cobro de matrícula universitaria estrictamente por crédito sobre los ingresos financieros de las instituciones de educación superior y sobre la cantidad de créditos que los estudiantes deciden cursar, en comparación con los esquemas de matrícula de tarifa plana o “plateau tuition”? Busca principalmente artículos científicos revisados por pares, estudios empíricos y documentos académicos publicados en revistas de educación superior, economía de la educación, finanzas universitarias o políticas públicas. Prioriza investigaciones que analicen universidades o sistemas de educación superior y que presenten evidencia cuantitativa. En la búsqueda: 1. Diferencia claramente entre: Strict per-credit tuition: el estudiante paga proporcionalmente por cada crédito cursado. Flat-rate / plateau tuition: el estudiante paga una tarifa fija dentro de un rango de créditos. 2. Identifica evidencia sobre los siguientes resultados: ingresos o revenue por matrícula de las instituciones; cambios en la cantidad de créditos matriculados por estudiante; incentivos para aumentar o reducir la carga académica; persistencia, avance académico o tiempo hasta la graduación cuando exista evidencia; efectos financieros o redistributivos entre estudiantes, programas o instituciones. 3. Prioriza estudios que permitan establecer una relación entre estructura de precios de matrícula → comportamiento de los estudiantes → resultados financieros institucionales. 4. Para cada estudio relevante, presenta: referencia bibliográfica completa; año de publicación; país o sistema educativo analizado; población o institución estudiada; metodología utilizada; principal resultado relacionado con matrícula por crédito; conclusión directamente respaldada por el estudio; DOI o enlace al documento cuando esté disponible. 5. No mezcles evidencia sobre matrícula por crédito con evidencia sobre otros mecanismos de precios. Si un estudio analiza únicamente tarifa plana, úsalo solo como evidencia comparativa y señala explícitamente esa diferencia. 6. No inventes referencias, autores, resultados ni conclusiones. Si una afirmación no está respaldada directamente por el artículo, indícalo. Prioriza estudios cuyo texto completo o resumen permita verificar la afirmación. 7. Finalmente, identifica entre 8 y 12 estudios particularmente relevantes para construir el estado del arte de un proyecto cuyo objetivo es simular cuánto habría ganado o perdido una universidad si hubiera aplicado un esquema de cobro estrictamente por créditos en distintos periodos y facultades. La revisión debe servir como fundamento académico para posteriormente construir una simulación contrafactual de ingresos, no para calcular todavía el resultado de una universidad específica. | G5: Chat sin fuentes ni navegación (control)
A6: Q1 | B6: Integrante 1 ROA | C6: B | D6: Consensus | E6: 2026-09-18 | F6: Realiza una revisión de literatura científica sobre la siguiente pregunta de investigación: ¿Qué efectos tiene el cobro de matrícula universitaria estrictamente por crédito sobre los ingresos financieros de las instituciones de educación superior y sobre la cantidad de créditos que los estudiantes deciden cursar, en comparación con los esquemas de matrícula de tarifa plana o “plateau tuition”? Busca principalmente artículos científicos revisados por pares, estudios empíricos y documentos académicos publicados en revistas de educación superior, economía de la educación, finanzas universitarias o políticas públicas. Prioriza investigaciones que analicen universidades o sistemas de educación superior y que presenten evidencia cuantitativa. En la búsqueda: 1. Diferencia claramente entre: Strict per-credit tuition: el estudiante paga proporcionalmente por cada crédito cursado. Flat-rate / plateau tuition: el estudiante paga una tarifa fija dentro de un rango de créditos. 2. Identifica evidencia sobre los siguientes resultados: ingresos o revenue por matrícula de las instituciones; cambios en la cantidad de créditos matriculados por estudiante; incentivos para aumentar o reducir la carga académica; persistencia, avance académico o tiempo hasta la graduación cuando exista evidencia; efectos financieros o redistributivos entre estudiantes, programas o instituciones. 3. Prioriza estudios que permitan establecer una relación entre estructura de precios de matrícula → comportamiento de los estudiantes → resultados financieros institucionales. 4. Para cada estudio relevante, presenta: referencia bibliográfica completa; año de publicación; país o sistema educativo analizado; población o institución estudiada; metodología utilizada; principal resultado relacionado con matrícula por crédito; conclusión directamente respaldada por el estudio; DOI o enlace al documento cuando esté disponible. 5. No mezcles evidencia sobre matrícula por crédito con evidencia sobre otros mecanismos de precios. Si un estudio analiza únicamente tarifa plana, úsalo solo como evidencia comparativa y señala explícitamente esa diferencia. 6. No inventes referencias, autores, resultados ni conclusiones. Si una afirmación no está respaldada directamente por el artículo, indícalo. Prioriza estudios cuyo texto completo o resumen permita verificar la afirmación. 7. Finalmente, identifica entre 8 y 12 estudios particularmente relevantes para construir el estado del arte de un proyecto cuyo objetivo es simular cuánto habría ganado o perdido una universidad si hubiera aplicado un esquema de cobro estrictamente por créditos en distintos periodos y facultades. La revisión debe servir como fundamento académico para posteriormente construir una simulación contrafactual de ingresos, no para calcular todavía el resultado de una universidad específica. | G6: Buscador conectado a bases bibliográficas
A7: Q1 | B7: Integrante 1 ROA | C7: C | D7: Notebook LM | E7: 46289 | F7: Realiza una revisión de literatura científica sobre la siguiente pregunta de investigación: ¿Qué efectos tiene el cobro de matrícula universitaria estrictamente por crédito sobre los ingresos financieros de las instituciones de educación superior y sobre la cantidad de créditos que los estudiantes deciden cursar, en comparación con los esquemas de matrícula de tarifa plana o “plateau tuition”? Busca principalmente artículos científicos revisados por pares, estudios empíricos y documentos académicos publicados en revistas de educación superior, economía de la educación, finanzas universitarias o políticas públicas. Prioriza investigaciones que analicen universidades o sistemas de educación superior y que presenten evidencia cuantitativa. En la búsqueda: 1. Diferencia claramente entre: Strict per-credit tuition: el estudiante paga proporcionalmente por cada crédito cursado. Flat-rate / plateau tuition: el estudiante paga una tarifa fija dentro de un rango de créditos. 2. Identifica evidencia sobre los siguientes resultados: ingresos o revenue por matrícula de las instituciones; cambios en la cantidad de créditos matriculados por estudiante; incentivos para aumentar o reducir la carga académica; persistencia, avance académico o tiempo hasta la graduación cuando exista evidencia; efectos financieros o redistributivos entre estudiantes, programas o instituciones. 3. Prioriza estudios que permitan establecer una relación entre estructura de precios de matrícula → comportamiento de los estudiantes → resultados financieros institucionales. 4. Para cada estudio relevante, presenta: referencia bibliográfica completa; año de publicación; país o sistema educativo analizado; población o institución estudiada; metodología utilizada; principal resultado relacionado con matrícula por crédito; conclusión directamente respaldada por el estudio; DOI o enlace al documento cuando esté disponible. 5. No mezcles evidencia sobre matrícula por crédito con evidencia sobre otros mecanismos de precios. Si un estudio analiza únicamente tarifa plana, úsalo solo como evidencia comparativa y señala explícitamente esa diferencia. 6. No inventes referencias, autores, resultados ni conclusiones. Si una afirmación no está respaldada directamente por el artículo, indícalo. Prioriza estudios cuyo texto completo o resumen permita verificar la afirmación. 7. Finalmente, identifica entre 8 y 12 estudios particularmente relevantes para construir el estado del arte de un proyecto cuyo objetivo es simular cuánto habría ganado o perdido una universidad si hubiera aplicado un esquema de cobro estrictamente por créditos en distintos periodos y facultades. La revisión debe servir como fundamento académico para posteriormente construir una simulación contrafactual de ingresos, no para calcular todavía el resultado de una universidad específica. Responde ÚNICAMENTE con base en los documentos que te he adjuntado. Para cada afirmación, cita el documento y la página exacta de donde sale. Si la pregunta de investigación no puede responderse con la información contenida en estos documentos, dilo explícitamente en vez de inventar o usar conocimiento externo. | G7: Contexto cerrado con sus propios PDF
